 * Serving Flask app "." (lazy loading)
 * Environment: development
 * Debug mode: on
Traceback (most recent call last):
  File "/root/.local/share/virtualenvs/root-BuDEOXnJ/bin/flask", line 8, in <module>
    sys.exit(main())
  File "/root/.local/share/virtualenvs/root-BuDEOXnJ/lib/python3.7/site-packages/flask/cli.py", line 966, in main
    cli.main(prog_name="python -m flask" if as_module else None)
  File "/root/.local/share/virtualenvs/root-BuDEOXnJ/lib/python3.7/site-packages/flask/cli.py", line 586, in main
    return super(FlaskGroup, self).main(*args, **kwargs)
  File "/root/.local/share/virtualenvs/root-BuDEOXnJ/lib/python3.7/site-packages/click/core.py", line 717, in main
    rv = self.invoke(ctx)
  File "/root/.local/share/virtualenvs/root-BuDEOXnJ/lib/python3.7/site-packages/click/core.py", line 1137, in invoke
    return _process_result(sub_ctx.command.invoke(sub_ctx))
  File "/root/.local/share/virtualenvs/root-BuDEOXnJ/lib/python3.7/site-packages/click/core.py", line 956, in invoke
    return ctx.invoke(self.callback, **ctx.params)
  File "/root/.local/share/virtualenvs/root-BuDEOXnJ/lib/python3.7/site-packages/click/core.py", line 555, in invoke
    return callback(*args, **kwargs)
  File "/root/.local/share/virtualenvs/root-BuDEOXnJ/lib/python3.7/site-packages/click/decorators.py", line 64, in new_func
    return ctx.invoke(f, obj, *args, **kwargs)
  File "/root/.local/share/virtualenvs/root-BuDEOXnJ/lib/python3.7/site-packages/click/core.py", line 555, in invoke
    return callback(*args, **kwargs)
  File "/root/.local/share/virtualenvs/root-BuDEOXnJ/lib/python3.7/site-packages/flask/cli.py", line 860, in run_command
    extra_files=extra_files,
  File "/root/.local/share/virtualenvs/root-BuDEOXnJ/lib/python3.7/site-packages/werkzeug/serving.py", line 1030, in run_simple
    s.bind(server_address)
OSError: [Errno 98] Address already in use
 * Serving Flask app "." (lazy loading)
 * Environment: development
 * Debug mode: on
 * Running on http://0.0.0.0:3000/ (Press CTRL+C to quit)
 * Restarting with stat
 * Debugger is active!
 * Debugger PIN: 273-232-662
196.52.43.56 - - [11/Feb/2020 00:34:09] "[33mGET / HTTP/1.0[0m" 404 -
122.228.19.80 - - [11/Feb/2020 01:29:13] "[33mGET / HTTP/1.1[0m" 404 -
 * Serving Flask app "." (lazy loading)
 * Environment: development
 * Debug mode: on
 * Running on http://0.0.0.0:3000/ (Press CTRL+C to quit)
 * Restarting with stat
 * Debugger is active!
 * Debugger PIN: 273-232-662
 * Detected change in '/root/projects/notes/__init__.py', reloading
 * Restarting with stat
 * Debugger is active!
 * Debugger PIN: 273-232-662
201.202.14.19 - - [11/Feb/2020 19:08:23] "[33mGET / HTTP/1.1[0m" 404 -
201.202.14.19 - - [11/Feb/2020 19:08:23] "[33mGET /favicon.ico HTTP/1.1[0m" 404 -
 * Detected change in '/root/projects/notes/__init__.py', reloading
 * Restarting with stat
 * Debugger is active!
 * Debugger PIN: 273-232-662
201.202.14.19 - - [11/Feb/2020 19:09:36] "[35m[1mGET /sign_up HTTP/1.1[0m" 500 -
Traceback (most recent call last):
  File "/root/.local/share/virtualenvs/root-BuDEOXnJ/lib/python3.7/site-packages/flask/app.py", line 2463, in __call__
    return self.wsgi_app(environ, start_response)
  File "/root/.local/share/virtualenvs/root-BuDEOXnJ/lib/python3.7/site-packages/flask/app.py", line 2449, in wsgi_app
    response = self.handle_exception(e)
  File "/root/.local/share/virtualenvs/root-BuDEOXnJ/lib/python3.7/site-packages/flask/app.py", line 1866, in handle_exception
    reraise(exc_type, exc_value, tb)
  File "/root/.local/share/virtualenvs/root-BuDEOXnJ/lib/python3.7/site-packages/flask/_compat.py", line 39, in reraise
    raise value
  File "/root/.local/share/virtualenvs/root-BuDEOXnJ/lib/python3.7/site-packages/flask/app.py", line 2446, in wsgi_app
    response = self.full_dispatch_request()
  File "/root/.local/share/virtualenvs/root-BuDEOXnJ/lib/python3.7/site-packages/flask/app.py", line 1951, in full_dispatch_request
    rv = self.handle_user_exception(e)
  File "/root/.local/share/virtualenvs/root-BuDEOXnJ/lib/python3.7/site-packages/flask/app.py", line 1820, in handle_user_exception
    reraise(exc_type, exc_value, tb)
  File "/root/.local/share/virtualenvs/root-BuDEOXnJ/lib/python3.7/site-packages/flask/_compat.py", line 39, in reraise
    raise value
  File "/root/.local/share/virtualenvs/root-BuDEOXnJ/lib/python3.7/site-packages/flask/app.py", line 1949, in full_dispatch_request
    rv = self.dispatch_request()
  File "/root/.local/share/virtualenvs/root-BuDEOXnJ/lib/python3.7/site-packages/flask/app.py", line 1935, in dispatch_request
    return self.view_functions[rule.endpoint](**req.view_args)
  File "/root/projects/notes/__init__.py", line 24, in sign_up
    return render_template('sign_up.html')
NameError: name 'render_template' is not defined
201.202.14.19 - - [11/Feb/2020 19:09:37] "[37mGET /sign_up?__debugger__=yes&cmd=resource&f=style.css HTTP/1.1[0m" 200 -
201.202.14.19 - - [11/Feb/2020 19:09:37] "[37mGET /sign_up?__debugger__=yes&cmd=resource&f=jquery.js HTTP/1.1[0m" 200 -
201.202.14.19 - - [11/Feb/2020 19:09:37] "[37mGET /sign_up?__debugger__=yes&cmd=resource&f=debugger.js HTTP/1.1[0m" 200 -
201.202.14.19 - - [11/Feb/2020 19:09:38] "[37mGET /sign_up?__debugger__=yes&cmd=resource&f=console.png HTTP/1.1[0m" 200 -
201.202.14.19 - - [11/Feb/2020 19:09:38] "[37mGET /sign_up?__debugger__=yes&cmd=resource&f=ubuntu.ttf HTTP/1.1[0m" 200 -
201.202.14.19 - - [11/Feb/2020 19:09:38] "[37mGET /sign_up?__debugger__=yes&cmd=resource&f=console.png HTTP/1.1[0m" 200 -
 * Detected change in '/root/projects/notes/__init__.py', reloading
 * Restarting with stat
 * Debugger is active!
 * Debugger PIN: 273-232-662
201.202.14.19 - - [11/Feb/2020 19:16:04] "[35m[1mGET /sign_up HTTP/1.1[0m" 500 -
Traceback (most recent call last):
  File "/root/.local/share/virtualenvs/root-BuDEOXnJ/lib/python3.7/site-packages/flask/app.py", line 2463, in __call__
    return self.wsgi_app(environ, start_response)
  File "/root/.local/share/virtualenvs/root-BuDEOXnJ/lib/python3.7/site-packages/flask/app.py", line 2449, in wsgi_app
    response = self.handle_exception(e)
  File "/root/.local/share/virtualenvs/root-BuDEOXnJ/lib/python3.7/site-packages/flask/app.py", line 1866, in handle_exception
    reraise(exc_type, exc_value, tb)
  File "/root/.local/share/virtualenvs/root-BuDEOXnJ/lib/python3.7/site-packages/flask/_compat.py", line 39, in reraise
    raise value
  File "/root/.local/share/virtualenvs/root-BuDEOXnJ/lib/python3.7/site-packages/flask/app.py", line 2446, in wsgi_app
    response = self.full_dispatch_request()
  File "/root/.local/share/virtualenvs/root-BuDEOXnJ/lib/python3.7/site-packages/flask/app.py", line 1951, in full_dispatch_request
    rv = self.handle_user_exception(e)
  File "/root/.local/share/virtualenvs/root-BuDEOXnJ/lib/python3.7/site-packages/flask/app.py", line 1820, in handle_user_exception
    reraise(exc_type, exc_value, tb)
  File "/root/.local/share/virtualenvs/root-BuDEOXnJ/lib/python3.7/site-packages/flask/_compat.py", line 39, in reraise
    raise value
  File "/root/.local/share/virtualenvs/root-BuDEOXnJ/lib/python3.7/site-packages/flask/app.py", line 1949, in full_dispatch_request
    rv = self.dispatch_request()
  File "/root/.local/share/virtualenvs/root-BuDEOXnJ/lib/python3.7/site-packages/flask/app.py", line 1935, in dispatch_request
    return self.view_functions[rule.endpoint](**req.view_args)
  File "/root/projects/notes/__init__.py", line 24, in sign_up
    return render_template('sign_up.html')
NameError: name 'render_template' is not defined
201.202.14.19 - - [11/Feb/2020 19:16:05] "[37mGET /sign_up?__debugger__=yes&cmd=resource&f=style.css HTTP/1.1[0m" 200 -
201.202.14.19 - - [11/Feb/2020 19:16:05] "[37mGET /sign_up?__debugger__=yes&cmd=resource&f=jquery.js HTTP/1.1[0m" 200 -
201.202.14.19 - - [11/Feb/2020 19:16:05] "[37mGET /sign_up?__debugger__=yes&cmd=resource&f=debugger.js HTTP/1.1[0m" 200 -
201.202.14.19 - - [11/Feb/2020 19:16:05] "[37mGET /sign_up?__debugger__=yes&cmd=resource&f=ubuntu.ttf HTTP/1.1[0m" 200 -
201.202.14.19 - - [11/Feb/2020 19:16:05] "[37mGET /sign_up?__debugger__=yes&cmd=resource&f=console.png HTTP/1.1[0m" 200 -
201.202.14.19 - - [11/Feb/2020 19:16:06] "[37mGET /sign_up?__debugger__=yes&cmd=resource&f=console.png HTTP/1.1[0m" 200 -
201.202.14.182 - - [11/Feb/2020 20:18:24] "[35m[1mGET /sign_up HTTP/1.1[0m" 500 -
Traceback (most recent call last):
  File "/root/.local/share/virtualenvs/root-BuDEOXnJ/lib/python3.7/site-packages/flask/app.py", line 2463, in __call__
    return self.wsgi_app(environ, start_response)
  File "/root/.local/share/virtualenvs/root-BuDEOXnJ/lib/python3.7/site-packages/flask/app.py", line 2449, in wsgi_app
    response = self.handle_exception(e)
  File "/root/.local/share/virtualenvs/root-BuDEOXnJ/lib/python3.7/site-packages/flask/app.py", line 1866, in handle_exception
    reraise(exc_type, exc_value, tb)
  File "/root/.local/share/virtualenvs/root-BuDEOXnJ/lib/python3.7/site-packages/flask/_compat.py", line 39, in reraise
    raise value
  File "/root/.local/share/virtualenvs/root-BuDEOXnJ/lib/python3.7/site-packages/flask/app.py", line 2446, in wsgi_app
    response = self.full_dispatch_request()
  File "/root/.local/share/virtualenvs/root-BuDEOXnJ/lib/python3.7/site-packages/flask/app.py", line 1951, in full_dispatch_request
    rv = self.handle_user_exception(e)
  File "/root/.local/share/virtualenvs/root-BuDEOXnJ/lib/python3.7/site-packages/flask/app.py", line 1820, in handle_user_exception
    reraise(exc_type, exc_value, tb)
  File "/root/.local/share/virtualenvs/root-BuDEOXnJ/lib/python3.7/site-packages/flask/_compat.py", line 39, in reraise
    raise value
  File "/root/.local/share/virtualenvs/root-BuDEOXnJ/lib/python3.7/site-packages/flask/app.py", line 1949, in full_dispatch_request
    rv = self.dispatch_request()
  File "/root/.local/share/virtualenvs/root-BuDEOXnJ/lib/python3.7/site-packages/flask/app.py", line 1935, in dispatch_request
    return self.view_functions[rule.endpoint](**req.view_args)
  File "/root/projects/notes/__init__.py", line 24, in sign_up
    return render_template('sign_up.html')
NameError: name 'render_template' is not defined
201.202.14.182 - - [11/Feb/2020 20:18:24] "[37mGET /sign_up?__debugger__=yes&cmd=resource&f=style.css HTTP/1.1[0m" 200 -
201.202.14.182 - - [11/Feb/2020 20:18:24] "[37mGET /sign_up?__debugger__=yes&cmd=resource&f=jquery.js HTTP/1.1[0m" 200 -
201.202.14.182 - - [11/Feb/2020 20:18:24] "[37mGET /sign_up?__debugger__=yes&cmd=resource&f=debugger.js HTTP/1.1[0m" 200 -
201.202.14.182 - - [11/Feb/2020 20:18:25] "[37mGET /sign_up?__debugger__=yes&cmd=resource&f=ubuntu.ttf HTTP/1.1[0m" 200 -
201.202.14.182 - - [11/Feb/2020 20:18:25] "[37mGET /sign_up?__debugger__=yes&cmd=resource&f=console.png HTTP/1.1[0m" 200 -
201.202.14.182 - - [11/Feb/2020 20:18:26] "[37mGET /sign_up?__debugger__=yes&cmd=resource&f=console.png HTTP/1.1[0m" 200 -
201.202.14.182 - - [11/Feb/2020 20:24:28] "[35m[1mGET /sign_up HTTP/1.1[0m" 500 -
Traceback (most recent call last):
  File "/root/.local/share/virtualenvs/root-BuDEOXnJ/lib/python3.7/site-packages/flask/app.py", line 2463, in __call__
    return self.wsgi_app(environ, start_response)
  File "/root/.local/share/virtualenvs/root-BuDEOXnJ/lib/python3.7/site-packages/flask/app.py", line 2449, in wsgi_app
    response = self.handle_exception(e)
  File "/root/.local/share/virtualenvs/root-BuDEOXnJ/lib/python3.7/site-packages/flask/app.py", line 1866, in handle_exception
    reraise(exc_type, exc_value, tb)
  File "/root/.local/share/virtualenvs/root-BuDEOXnJ/lib/python3.7/site-packages/flask/_compat.py", line 39, in reraise
    raise value
  File "/root/.local/share/virtualenvs/root-BuDEOXnJ/lib/python3.7/site-packages/flask/app.py", line 2446, in wsgi_app
    response = self.full_dispatch_request()
  File "/root/.local/share/virtualenvs/root-BuDEOXnJ/lib/python3.7/site-packages/flask/app.py", line 1951, in full_dispatch_request
    rv = self.handle_user_exception(e)
  File "/root/.local/share/virtualenvs/root-BuDEOXnJ/lib/python3.7/site-packages/flask/app.py", line 1820, in handle_user_exception
    reraise(exc_type, exc_value, tb)
  File "/root/.local/share/virtualenvs/root-BuDEOXnJ/lib/python3.7/site-packages/flask/_compat.py", line 39, in reraise
    raise value
  File "/root/.local/share/virtualenvs/root-BuDEOXnJ/lib/python3.7/site-packages/flask/app.py", line 1949, in full_dispatch_request
    rv = self.dispatch_request()
  File "/root/.local/share/virtualenvs/root-BuDEOXnJ/lib/python3.7/site-packages/flask/app.py", line 1935, in dispatch_request
    return self.view_functions[rule.endpoint](**req.view_args)
  File "/root/projects/notes/__init__.py", line 24, in sign_up
    return render_template('sign_up.html')
NameError: name 'render_template' is not defined
201.202.14.182 - - [11/Feb/2020 20:24:28] "[37mGET /sign_up?__debugger__=yes&cmd=resource&f=style.css HTTP/1.1[0m" 200 -
201.202.14.182 - - [11/Feb/2020 20:24:28] "[37mGET /sign_up?__debugger__=yes&cmd=resource&f=jquery.js HTTP/1.1[0m" 200 -
201.202.14.182 - - [11/Feb/2020 20:24:28] "[37mGET /sign_up?__debugger__=yes&cmd=resource&f=debugger.js HTTP/1.1[0m" 200 -
201.202.14.182 - - [11/Feb/2020 20:24:29] "[37mGET /sign_up?__debugger__=yes&cmd=resource&f=ubuntu.ttf HTTP/1.1[0m" 200 -
201.202.14.182 - - [11/Feb/2020 20:24:29] "[37mGET /sign_up?__debugger__=yes&cmd=resource&f=console.png HTTP/1.1[0m" 200 -
201.202.14.182 - - [11/Feb/2020 20:24:29] "[37mGET /sign_up?__debugger__=yes&cmd=resource&f=console.png HTTP/1.1[0m" 200 -
 * Serving Flask app "." (lazy loading)
 * Environment: development
 * Debug mode: on
 * Running on http://0.0.0.0:3000/ (Press CTRL+C to quit)
 * Restarting with stat
 * Debugger is active!
 * Debugger PIN: 273-232-662
 * Serving Flask app "." (lazy loading)
 * Environment: development
 * Debug mode: on
Traceback (most recent call last):
  File "/root/.local/share/virtualenvs/root-BuDEOXnJ/bin/flask", line 8, in <module>
    sys.exit(main())
  File "/root/.local/share/virtualenvs/root-BuDEOXnJ/lib/python3.7/site-packages/flask/cli.py", line 966, in main
    cli.main(prog_name="python -m flask" if as_module else None)
  File "/root/.local/share/virtualenvs/root-BuDEOXnJ/lib/python3.7/site-packages/flask/cli.py", line 586, in main
    return super(FlaskGroup, self).main(*args, **kwargs)
  File "/root/.local/share/virtualenvs/root-BuDEOXnJ/lib/python3.7/site-packages/click/core.py", line 717, in main
    rv = self.invoke(ctx)
  File "/root/.local/share/virtualenvs/root-BuDEOXnJ/lib/python3.7/site-packages/click/core.py", line 1137, in invoke
    return _process_result(sub_ctx.command.invoke(sub_ctx))
  File "/root/.local/share/virtualenvs/root-BuDEOXnJ/lib/python3.7/site-packages/click/core.py", line 956, in invoke
    return ctx.invoke(self.callback, **ctx.params)
  File "/root/.local/share/virtualenvs/root-BuDEOXnJ/lib/python3.7/site-packages/click/core.py", line 555, in invoke
    return callback(*args, **kwargs)
  File "/root/.local/share/virtualenvs/root-BuDEOXnJ/lib/python3.7/site-packages/click/decorators.py", line 64, in new_func
    return ctx.invoke(f, obj, *args, **kwargs)
  File "/root/.local/share/virtualenvs/root-BuDEOXnJ/lib/python3.7/site-packages/click/core.py", line 555, in invoke
    return callback(*args, **kwargs)
  File "/root/.local/share/virtualenvs/root-BuDEOXnJ/lib/python3.7/site-packages/flask/cli.py", line 860, in run_command
    extra_files=extra_files,
  File "/root/.local/share/virtualenvs/root-BuDEOXnJ/lib/python3.7/site-packages/werkzeug/serving.py", line 1030, in run_simple
    s.bind(server_address)
OSError: [Errno 98] Address already in use
201.202.14.182 - - [12/Feb/2020 17:12:43] "[37mGET /sign_up HTTP/1.1[0m" 200 -
201.202.14.182 - - [12/Feb/2020 17:12:44] "[37mGET /static/bulma.min.css HTTP/1.1[0m" 200 -
201.202.14.182 - - [12/Feb/2020 17:12:44] "[37mGET /static/highlight.min.css HTTP/1.1[0m" 200 -
201.202.14.182 - - [12/Feb/2020 17:12:44] "[37mGET /static/styles.css HTTP/1.1[0m" 200 -
201.202.14.182 - - [12/Feb/2020 17:12:44] "[37mGET /static/app.js HTTP/1.1[0m" 200 -
201.202.14.182 - - [12/Feb/2020 17:12:44] "[37mGET /static/highlight.min.js HTTP/1.1[0m" 200 -
201.202.14.182 - - [12/Feb/2020 17:12:45] "[33mGET /favicon.ico HTTP/1.1[0m" 404 -
